Workbook

Sheet 核验总表
A1: 清单编号 | B1: 领域 | C1: 清单要求 | D1: 核验状态 | E1: 事实摘要 | F1: 证据定位 | G1: 资料缺口 | H1: 风险等级 | I1: 处置类型 | J1: 反馈意见 | K1: 是否需人工复核 | L1: 关联反馈编号
A2: CORP-01 | B2: 主体资格 | C2: 请提交目标公司及其分支、控股或参股企业的现行营业执照、登记事项报告或同等主体资格文件。 | D2: 已满足 | E2: 已提供相关资料（01.1 ）。 | F2: 01_主体资格及历史沿革__01.1_登记事项及关键变更档案_20260710｜正文 | G2: 按清单要求补充其余子项（如适用）。 | H2: LOW | I2: RFI | J2: 无。 | K2: 否
A3: CORP-02 | B3: 主体资格 | C3: 请提交目标公司自设立以来全套工商登记档案，涵盖设立、名称、住所、注册资本、股东及董监高历次变更。 | D3: 已满足 | E3: 已提供相关资料（01.1 ）。 | F3: 01_主体资格及历史沿革__01.1_登记事项及关键变更档案_20260710｜正文 | G3: 按清单要求补充其余子项（如适用）。 | H3: LOW | I3: RFI | J3: 无。 | K3: 否
A4: CORP-03 | B4: 主体资格 | C4: 请提交现行有效的公司章程及自设立以来的章程、修正案或重述文本。 | D4: 已满足 | E4: 已提供相关资料（01.2、01.1 ）。 | F4: 01_主体资格及历史沿革__01.1_登记事项及关键变更档案_20260710｜正文 | G4: 按清单要求补充其余子项（如适用）。；与CT-01矛盾相关（详见跨文件矛盾） | H4: LOW | I4: RFI | J4: 无。 | K4: 否
A5: CORP-04 | B5: 主体资格 | C5: 请提供集团组织结构图，列示关联公司、分支机构、持股比例、实际控制关系与主营业务。 | D5: 已满足 | E5: 已提供相关资料（01.3 ）。 | F5: 01_主体资格及历史沿革__01.1_登记事项及关键变更档案_20260710｜正文 | G5: 按清单要求补充其余子项（如适用）。 | H5: LOW | I5: RFI | J5: 无。 | K5: 否
A6: CORP-05 | B6: 主体资格 | C6: 请列示目标公司对外投资、合伙份额、联营或合营安排及相关协议。 | D6: 已满足 | E6: 已提供相关资料（01.3 ）。 | F6: 01_主体资格及历史沿革__01.1_登记事项及关键变更档案_20260710｜正文 | G6: 按清单要求补充其余子项（如适用）。 | H6: LOW | I6: RFI | J6: 无。 | K6: 否
A7: CORP-06 | B7: 主体资格 | C7: 请说明并证明文件实际控制人、一致行动、委托持股、信托或代持安排。 | D7: 已满足 | E7: 已提供相关资料（01.3、02.1 ）。 | F7: 01_主体资格及历史沿革__01.1_登记事项及关键变更档案_20260710｜正文 | G7: 按清单要求补充其余子项（如适用）。 | H7: LOW | I7: RFI | J7: 无。 | K7: 否
A8: CORP-07 | B8: 主体资格 | C8: 请提供最近三年年度报告、公示信息及经营异常、严重违法失信名单说明。 | D8: 已满足 | E8: 已提供相关资料（01.1 ）。 | F8: 01_主体资格及历史沿革__01.1_登记事项及关键变更档案_20260710｜正文 | G8: 按清单要求补充其余子项（如适用）。 | H8: LOW | I8: RFI | J8: 提供近三年年度报告与经营异常/失信名单专项说明。 | K8: 否 | L8: F-13
A9: CAP-01 | B9: 股权出资 | C9: 请提供截至基准日的股权结构表，列明股东、认缴额、实缴额、持股比例、出资方式与出资期限。 | D9: 资料冲突 | E9: 云栖智联员工持股平台（有限合伙）：比例在文件中记载不一（8%/10%/22%/33%/45%，见 01_主体资格及历史沿革__01.1_登记事项及关键变更档案_20260710、01_主体资格及历史沿革__01.2_公司章程_202409修订_签署版、02_股权及公司治理__02.1_股权结构及历次变动台账_20260712、02_股权及公司治理__02.3_2024股权转让及决议文件汇编）。该冲突直接影响收购基准股权表与本次交易对价，并可能触发历史转让协议效力与税务复核。 | F9: 01_主体资格及历史沿革__01.1_登记事项及关键变更档案_20260710 01_主体资格及历史沿革__01.2_公司章程_202409修订_签署版 02_股权及公司治理__02.1_股权结构及历次变动台账_20260712 02_股权及公司治理__02.3_2024股权转让及决议文件汇编 | G9: 统一并更正多源不一致文件，作为交易先决。 | H9: HIGH | I9: CP | J9: 统一并更正股权比例，以登记机关备案文本为准，提供更正说明与转让对价支付凭证。 | K9: 是 | L9: F-01
A10: CAP-02 | B10: 股权出资 | C10: 请提供历次验资报告、银行入账凭证、出资证明书等实缴证明。 | D10: 部分满足 | E10: 股权结构台账显示：林远 认缴1200/实缴1000；华晟创业投资有限公司 认缴500/实缴500；云栖智联员工持股平台（有限合伙） 认缴160/实缴160；其他创始股东 认缴140/实缴140。存在未实缴出资。 | F10: 02_股权及公司治理__02.1_股权结构及历次变动台账_20260712｜正文 | G10: 实缴凭证与出资期限届满事项待核。 | H10: HIGH | I10: CP | J10: 统一并更正股权比例，以登记机关备案文本为准，提供更正说明与转让对价支付凭证。 提供全额验资报告与银行入账凭证，确认实缴与出资期限。 | K10: 是 | L10: F-01、F-02
A11: CAP-03 | B11: 股权出资 | C11: 请提供历次股权转让、增资、减资、回购或注销文件及对应付款、完税与登记材料。 | D11: 部分满足 | E11: 股权结构台账显示：林远 认缴1200/实缴1000；华晟创业投资有限公司 认缴500/实缴500；云栖智联员工持股平台（有限合伙） 认缴160/实缴160；其他创始股东 认缴140/实缴140。存在未实缴出资。 | F11: 02_股权及公司治理__02.1_股权结构及历次变动台账_20260712｜正文 | G11: 实缴凭证与出资期限届满事项待核。 | H11: HIGH | I11: CP | J11: 统一并更正股权比例，以登记机关备案文本为准，提供更正说明与转让对价支付凭证。 | K11: 是 | L11: F-01
A12: CAP-04 | B12: 股权出资 | C12: 请提供员工持股平台、股权激励、期权、限制性权益或虚拟股等完整文件与台账。 | D12: 部分满足 | E12: 股权结构台账显示：林远 认缴1200/实缴1000；华晟创业投资有限公司 认缴500/实缴500；云栖智联员工持股平台（有限合伙） 认缴160/实缴160；其他创始股东 认缴140/实缴140。存在未实缴出资。 | F12: 02_股权及公司治理__02.1_股权结构及历次变动台账_20260712｜正文 | G12: 实缴凭证与出资期限届满事项待核。；与CT-01矛盾相关（详见跨文件矛盾） | H12: HIGH | I12: CP | J12: 统一并更正股权比例，以登记机关备案文本为准，提供更正说明与转让对价支付凭证。 | K12: 是 | L12: F-01
A13: CAP-05 | B13: 股权出资 | C13: 请提供股权质押、冻结、查封、优先购买、共同出售、随售或回购等权利负担文件。 | D13: 部分满足 | E13: 股权结构台账显示：林远 认缴1200/实缴1000；华晟创业投资有限公司 认缴500/实缴500；云栖智联员工持股平台（有限合伙） 认缴160/实缴160；其他创始股东 认缴140/实缴140。存在未实缴出资。 | F13: 02_股权及公司治理__02.1_股权结构及历次变动台账_20260712｜正文 | G13: 实缴凭证与出资期限届满事项待核。；与CT-01矛盾相关（详见跨文件矛盾） | H13: HIGH | I13: CP | J13: 统一并更正股权比例，以登记机关备案文本为准，提供更正说明与转让对价支付凭证。 | K13: 是 | L13: F-01
A14: CAP-06 | B14: 股权出资 | C14: 请提供股东协议、投资协议及其补充协议，并列明尚存续的特殊股东权利。 | D14: 部分满足 | E14: 股权结构台账显示：林远 认缴1200/实缴1000；华晟创业投资有限公司 认缴500/实缴500；云栖智联员工持股平台（有限合伙） 认缴160/实缴160；其他创始股东 认缴140/实缴140。存在未实缴出资。 | F14: 02_股权及公司治理__02.1_股权结构及历次变动台账_20260712｜正文 | G14: 实缴凭证与出资期限届满事项待核。 | H14: HIGH | I14: CP | J14: 统一并更正股权比例，以登记机关备案文本为准，提供更正说明与转让对价支付凭证。 | K14: 是 | L14: F-01
A15: GOV-01 | B15: 公司治理 | C15: 请提供现任及近三年董事、监事、高管名单、任职与辞任文件。 | D15: 已满足 | E15: 已提供相关资料（01.1、02.4 ）。 | F15: 02_股权及公司治理__02.4_治理决议汇编_2024-2026｜正文 | G15: 按清单要求补充其余子项（如适用）。 | H15: LOW | I15: CP | J15: 无。 | K15: 否
A16: GOV-02 | B16: 公司治理 | C16: 请提供近三年股东会、董事会与监事决定/会议通知、签到、议案、记录及决议。 | D16: 部分满足 | E16: 治理决议汇编含股东会/董事会决议；章程规定董事会法定人数约 4 名董事，需核签署人数是否达标。 | F16: 02_股权及公司治理__02.4_治理决议汇编_2024-2026｜正文 | G16: 部分决议签署董事人数与法定人数待核（见 K-05）。 | H16: MEDIUM | I16: CP | J16: 补正董事会决议法定人数瑕疵或取得贷款人确认。 | K16: 否 | L16: F-04
A17: GOV-03 | B17: 公司治理 | C17: 请提供关联交易、对外担保、融资、重大投资与资产处置的审批制度及对应文件。 | D17: 已满足 | E17: 已提供相关资料（01.2、02.4、03.4 ）。 | F17: 02_股权及公司治理__02.4_治理决议汇编_2024-2026｜正文 | G17: 按清单要求补充其余子项（如适用）。 | H17: LOW | I17: CP | J17: 补充关联交易与对外担保专项管理制度及历史审批记录。 | K17: 否 | L17: F-14
A18: GOV-04 | B18: 公司治理 | C18: 请提供法定代表人、印章、网银 U 盾与授权委托管理制度及用印台账。 | D18: 已满足 | E18: 已提供相关资料（00.2 ）。 | F18: 02_股权及公司治理__02.4_治理决议汇编_2024-2026｜正文 | G18: 按清单要求补充其余子项（如适用）。 | H18: LOW | I18: CP | J18: 提供法定代表人/印章/网银U盾管理制度与用印台账。 | K18: 否 | L18: F-19
A19: GOV-05 | B19: 公司治理 | C19: 请提供尚未执行完毕或可能影响本次交易的股东会、董事会决议及授权。 | D19: 已满足 | E19: 已提供相关资料（02.4 ）。 | F19: 02_股权及公司治理__02.4_治理决议汇编_2024-2026｜正文 | G19: 按清单要求补充其余子项（如适用）。 | H19: LOW | I19: CP | J19: 提供尚未执行完毕或影响本次交易的股东会/董事会决议及授权文件。 | K19: 否 | L19: F-20
A20: CON-01 | B20: 重大合同 | C20: 请提供截至基准日的重大合同台账，至少列明相对方、金额、期限、履行状态与控制权变更等条款。 | D20: 部分满足 | E20: 合同台账列示重大合同 4 份；其中 3 份含控制权变更/转让限制条款（如 C-01）。 | F20: 03_重大合同及融资__03.1_重大合同台账_20260712｜正文 | G20: 控制权变更需取得相对方确认/豁免，待核具体条款文本。 | H20: HIGH | I20: COVENANT | J20: 无。 | K20: 是
A21: CON-02 | B21: 重大合同 | C21: 请提供前十大客户及收入占比、对应主协议、订单、补充协议与争议材料。 | D21: 部分满足 | E21: 合同台账列示重大合同 4 份；其中 3 份含控制权变更/转让限制条款（如 C-01）。 | F21: 03_重大合同及融资__03.1_重大合同台账_20260712｜正文 | G21: 控制权变更需取得相对方确认/豁免，待核具体条款文本。 | H21: HIGH | I21: COVENANT | J21: 就控制权变更取得核心客户、贷款人与出租方确认或豁免，纳入交易承诺。 提供前十大客户/供应商主协议、订单及收入/采购占比明细。 | K21: 是 | L21: F-05、F-10
A22: CON-03 | B22: 重大合同 | C22: 请提供前十大供应商及采购占比、采购、云服务、外包与技术服务的协议。 | D22: 部分满足 | E22: 合同台账列示重大合同 4 份；其中 3 份含控制权变更/转让限制条款（如 C-01）。 | F22: 03_重大合同及融资__03.1_重大合同台账_20260712｜正文 | G22: 控制权变更需取得相对方确认/豁免，待核具体条款文本。 | H22: HIGH | I22: COVENANT | J22: 提供前十大客户/供应商主协议、订单及收入/采购占比明细。 | K22: 是 | L22: F-10
A23: CON-04 | B23: 重大合同 | C23: 请提供经销、代理、渠道、合作伙伴或联合销售协议及相关返利政策。 | D23: 部分满足 | E23: 合同台账列示重大合同 4 份；其中 3 份含控制权变更/转让限制条款（如 C-01）。 | F23: 03_重大合同及融资__03.1_重大合同台账_20260712｜正文 | G23: 控制权变更需取得相对方确认/豁免，待核具体条款文本。 | H23: HIGH | I23: COVENANT | J23: 无。 | K23: 是
A24: CON-05 | B24: 重大合同 | C24: 请提供借款、授信、融资租赁、保理、票据、可转债等融资文件与余额清单。 | D24: 部分满足 | E24: 合同台账列示重大合同 4 份；其中 3 份含控制权变更/转让限制条款（如 C-01）。 | F24: 03_重大合同及融资__03.1_重大合同台账_20260712｜正文 | G24: 控制权变更需取得相对方确认/豁免，待核具体条款文本。 | H24: HIGH | I24: COVENANT | J24: 就控制权变更取得核心客户、贷款人与出租方确认或豁免，纳入交易承诺。 | K24: 是 | L24: F-05
A25: CON-06 | B25: 重大合同 | C25: 请提供目标公司提供或接受的保证、抵押、质押、安慰函等增信文件。 | D25: 部分满足 | E25: 合同台账列示重大合同 4 份；其中 3 份含控制权变更/转让限制条款（如 C-01）。 | F25: 03_重大合同及融资__03.1_重大合同台账_20260712｜正文 | G25: 控制权变更需取得相对方确认/豁免，待核具体条款文本。 | H25: HIGH | I25: COVENANT | J25: 无。 | K25: 是
A26: CON-07 | B26: 重大合同 | C26: 请提供与关联方之间的采购、销售、许可、服务、资金拆借、费用分摊与资产使用协议。 | D26: 部分满足 | E26: 合同台账列示重大合同 4 份；其中 3 份含控制权变更/转让限制条款（如 C-01）。 | F26: 03_重大合同及融资__03.1_重大合同台账_20260712｜正文 | G26: 控制权变更需取得相对方确认/豁免，待核具体条款文本。 | H26: HIGH | I26: COVENANT | J26: 无。 | K26: 是
A27: CON-08 | B27: 重大合同 | C27: 请提供含重大违约、索赔、暂停履行、解除或未完成整改的合同及往来文件。 | D27: 部分满足 | E27: 合同台账列示重大合同 4 份；其中 3 份含控制权变更/转让限制条款（如 C-01）。 | F27: 03_重大合同及融资__03.1_重大合同台账_20260712｜正文 | G27: 控制权变更需取得相对方确认/豁免，待核具体条款文本。；与CT-03矛盾相关（详见跨文件矛盾） | H27: HIGH | I27: COVENANT | J27: 无。 | K27: 是
A28: IP-01 | B28: 知识产权 | C28: 请提供专利、商标、软著、作品、域名及商业秘密清单，列明权利人、状态、期限与产品。 | D28: 部分满足 | E28: 知识产权清单列示 5 项；其中核心成果登记权利人为关联方（云栖智算（杭州）有限公司），未纳入收购范围。 | F28: 04_知识产权及信息技术__04.1_知识产权清单_202607｜正文 | G28: 核心IP权属转回/独占许可文件待提供。 | H28: HIGH | I28: CP | J28: 将核心IP转回/独占许可并办理权属变更登记，提供转让/许可协议。 | K28: 是 | L28: F-03
A29: IP-02 | B29: 知识产权 | C29: 请提供核心知识产权证书、申请文件、年费/续展凭证与权属变更文件。 | D29: 部分满足 | E29: 知识产权清单列示 5 项；其中核心成果登记权利人为关联方（云栖智算（杭州）有限公司），未纳入收购范围。 | F29: 04_知识产权及信息技术__04.1_知识产权清单_202607｜正文 | G29: 核心IP权属转回/独占许可文件待提供。 | H29: HIGH | I29: CP | J29: 将核心IP转回/独占许可并办理权属变更登记，提供转让/许可协议。 | K29: 是 | L29: F-03
A30: IP-03 | B30: 知识产权 | C30: 请提供员工、创始人、顾问、外包与研发方签署的保密、职务成果及 IP 转让文件。 | D30: 部分满足 | E30: 知识产权清单列示 5 项；其中核心成果登记权利人为关联方（云栖智算（杭州）有限公司），未纳入收购范围。 | F30: 04_知识产权及信息技术__04.1_知识产权清单_202607｜正文 | G30: 核心IP权属转回/独占许可文件待提供。 | H30: HIGH | I30: CP | J30: 将核心IP转回/独占许可并办理权属变更登记，提供转让/许可协议。 | K30: 是 | L30: F-03
A31: IP-04 | B31: 知识产权 | C31: 请提供知识产权许可、技术引进、联合/委托开发、开源与第三方代码使用文件。 | D31: 部分满足 | E31: 知识产权清单列示 5 项；其中核心成果登记权利人为关联方（云栖智算（杭州）有限公司），未纳入收购范围。 | F31: 04_知识产权及信息技术__04.1_知识产权清单_202607｜正文 | G31: 核心IP权属转回/独占许可文件待提供。 | H31: HIGH | I31: CP | J31: 将核心IP转回/独占许可并办理权属变更登记，提供转让/许可协议。 完成开源AGPL/SSPL专项法务复核并闭环（修改后网络提供义务）。 | K31: 是 | L31: F-03、F-11
A32: IP-05 | B32: 知识产权 | C32: 请提供开源软件物料清单（SBOM）、许可证、使用方式、修改情况与合规审查记录。 | D32: 部分满足 | E32: 知识产权清单列示 5 项；其中核心成果登记权利人为关联方（云栖智算（杭州）有限公司），未纳入收购范围。 | F32: 04_知识产权及信息技术__04.1_知识产权清单_202607｜正文 | G32: 核心IP权属转回/独占许可文件待提供。 | H32: HIGH | I32: CP | J32: 将核心IP转回/独占许可并办理权属变更登记，提供转让/许可协议。 完成开源AGPL/SSPL专项法务复核并闭环（修改后网络提供义务）。 | K32: 是 | L32: F-03、F-11
A33: IP-06 | B33: 知识产权 | C33: 请提供知识产权侵权主张、异议、无效、撤销、警告函、和解及共存安排。 | D33: 部分满足 | E33: 知识产权清单列示 5 项；其中核心成果登记权利人为关联方（云栖智算（杭州）有限公司），未纳入收购范围。 | F33: 04_知识产权及信息技术__04.1_知识产权清单_202607｜正文 | G33: 核心IP权属转回/独占许可文件待提供。 | H33: HIGH | I33: CP | J33: 将核心IP转回/独占许可并办理权属变更登记，提供转让/许可协议。 | K33: 是 | L33: F-03
A34: IP-07 | B34: 知识产权 | C34: 请提供研发、代码仓库、权限、发布、备份、灾备与离职交接制度及执行记录。 | D34: 部分满足 | E34: 知识产权清单列示 5 项；其中核心成果登记权利人为关联方（云栖智算（杭州）有限公司），未纳入收购范围。 | F34: 04_知识产权及信息技术__04.1_知识产权清单_202607｜正文 | G34: 核心IP权属转回/独占许可文件待提供。 | H34: HIGH | I34: CP | J34: 将核心IP转回/独占许可并办理权属变更登记，提供转让/许可协议。 | K34: 是 | L34: F-03
A35: HR-01 | B35: 劳动人事 | C35: 请提供员工名册，列明岗位、入职、合同期限、地点、薪酬、社保与派遣情况。 | D35: 部分满足 | E35: 员工名册 5 人；关键人员（沈澈）合同状态：未签署稿。 | F35: 05_劳动人事__05.1_员工名册及社保情况_202606｜正文 | G35: 核心人员劳动合同与IP协议签署待补。 | H35: HIGH | I35: CP | J35: 无。 | K35: 是
A36: HR-02 | B36: 劳动人事 | C36: 请提供劳动合同、保密、IP、竞业限制、奖金标准文本与关键员工签署版。 | D36: 部分满足 | E36: 员工名册 5 人；关键人员（沈澈）合同状态：未签署稿。 | F36: 05_劳动人事__05.1_员工名册及社保情况_202606｜正文 | G36: 核心人员劳动合同与IP协议签署待补。 | H36: HIGH | I36: CP | J36: 交割前完成CTO等核心人员劳动合同及IP协议签署，或作为陈述保证/先决。 | K36: 是 | L36: F-07
A37: HR-03 | B37: 劳动人事 | C37: 请提供员工手册、奖惩、工时、休假、薪酬、绩效与个人信息处理制度及公示记录。 | D37: 部分满足 | E37: 员工名册 5 人；关键人员（沈澈）合同状态：未签署稿。 | F37: 05_劳动人事__05.1_员工名册及社保情况_202606｜正文 | G37: 核心人员劳动合同与IP协议签署待补。 | H37: HIGH | I37: CP | J37: 补充员工手册民主公示记录与关键员工IP/竞业限制签署版。 | K37: 是 | L37: F-12
A38: HR-04 | B38: 劳动人事 | C38: 请提供近三年劳动争议、工伤、裁员、补偿、社保补缴与员工投诉清单。 | D38: 部分满足 | E38: 员工名册 5 人；关键人员（沈澈）合同状态：未签署稿。 | F38: 05_劳动人事__05.1_员工名册及社保情况_202606｜正文 | G38: 核心人员劳动合同与IP协议签署待补。 | H38: HIGH | I38: CP | J38: 无。 | K38: 是
A39: HR-05 | B39: 劳动人事 | C39: 请提供关键人员留任、控制权变更奖金、遣散、加速归属或交易相关激励安排。 | D39: 部分满足 | E39: 员工名册 5 人；关键人员（沈澈）合同状态：未签署稿。 | F39: 05_劳动人事__05.1_员工名册及社保情况_202606｜正文 | G39: 核心人员劳动合同与IP协议签署待补。 | H39: HIGH | I39: CP | J39: 交割前完成CTO等核心人员劳动合同及IP协议签署，或作为陈述保证/先决。 | K39: 是 | L39: F-07
A40: DATA-01 | B40: 数据合规 | C40: 请提供业务数据地图与数据清单，说明来源、主体、字段、目的、系统与接收方。 | D40: 部分满足 | E40: 隐私政策与云账单显示存在境外区域部署（新加坡：应用日志、IP、账号标识符（含个人信息））。 | F40: 06_数据合规及业务资质__06.1_隐私政策与数据处理说明_2026｜正文 | G40: 数据出境合规材料（标准合同/评估）待提供。 | H40: MEDIUM | I40: RFI | J40: 澄清境外（新加坡）部署资源的数据属性与出境合规：列明跨境传输字段、接收方与目的，提供告知同意记录、与境外接收方签订的标准合同/安全评估及个人信息保护影响评估（PIA）文件。 | K40: 否 | L40: F-08
...

Sheet 证据索引
A1: 被引用文件 | B1: 精确定位（章节/工作表/单元格/页码） | C1: 关联清单编号
A2: 01_主体资格及历史沿革__01.1_登记事项及关键变更档案_20260710 | B2: 正文 | C2: CORP-01、CORP-02、CORP-03、CORP-04、CORP-05、CORP-06、CORP-07、CAP-01、DISP-03、PROP-02
A3: 01_主体资格及历史沿革__01.2_公司章程_202409修订_签署版 | C3: CAP-01、DISP-03、PROP-02
A4: 02_股权及公司治理__02.1_股权结构及历次变动台账_20260712 | B4: 正文 | C4: CAP-01、CAP-02、CAP-03、CAP-04、CAP-05、CAP-06、DISP-03、PROP-02
A5: 02_股权及公司治理__02.3_2024股权转让及决议文件汇编 | C5: CAP-01、DISP-03、PROP-02
A6: 02_股权及公司治理__02.4_治理决议汇编_2024-2026 | B6: 正文 | C6: GOV-01、GOV-02、GOV-03、GOV-04、GOV-05、DISP-03、PROP-02
A7: 03_重大合同及融资__03.1_重大合同台账_20260712 | B7: 正文 | C7: CON-01、CON-02、CON-03、CON-04、CON-05、CON-06、CON-07、CON-08、DISP-01、DISP-03、PROP-02
A8: 04_知识产权及信息技术__04.1_知识产权清单_202607 | B8: 正文 | C8: IP-01、IP-02、IP-03、IP-04、IP-05、IP-06、IP-07、DISP-03、PROP-02
A9: 05_劳动人事__05.1_员工名册及社保情况_202606 | B9: 正文 | C9: HR-01、HR-02、HR-03、HR-04、HR-05、DISP-03、PROP-02
A10: 06_数据合规及业务资质__06.1_隐私政策与数据处理说明_2026 | B10: 正文 | C10: DATA-01、DATA-02、DATA-03、DATA-04、DATA-05、DATA-06、DISP-03、PROP-02
A11: 06_数据合规及业务资质__06.2_云服务账单及资源区域_202601-06 | C11: DATA-03、DISP-03、PROP-02
A12: 06_数据合规及业务资质__06.3_业务许可证及认证汇编 | B12: 正文 | C12: REG-01、REG-02、REG-03、DISP-03、PROP-02
A13: 07_争议债务及保险__07.3_供应商索赔律师函_20260618 | C13: DISP-01、DISP-03、PROP-02
A14: 07_争议债务及保险__07.1_诉讼仲裁及或有负债清单_202607 | B14: 正文 | C14: DISP-01、DISP-02、DISP-03、PROP-02
A15: （无） | C15: DISP-03、PROP-02
A16: 08_物业及其他__08.1_研发场地租赁合同及补充协议 | B16: 正文 | C16: DISP-03、PROP-01、PROP-02

Sheet 跨文件矛盾
A1: 矛盾编号 | B1: 严重度 | C1: 矛盾主题 | D1: 冲突文件 | E1: 关联清单编号 | F1: 矛盾说明 | G1: 建议处置
A2: CT-01 | B2: HIGH | C2: 股权结构多源比例不一致 | D2: 01_主体资格及历史沿革__01.1_登记事项及关键变更档案_20260710 01_主体资格及历史沿革__01.2_公司章程_202409修订_签署版 02_股权及公司治理__02.1_股权结构及历次变动台账_20260712 02_股权及公司治理__02.3_2024股权转让及决议文件汇编 | E2: CAP-01、CORP-03、CAP-04、CAP-05 | F2: 云栖智联员工持股平台（有限合伙）：比例在文件中记载不一（8%/10%/22%/33%/45%，见 01_主体资格及历史沿革__01.1_登记事项及关键变更档案_20260710、01_主体资格及历史沿革__01.2_公司章程_202409修订_签署版、02_股权及公司治理__02.1_股权结构及历次变动台账_20260712、02_股权及公司治理__02.3_2024股权转让及决议文件汇编）。该冲突直接影响收购基准股权表与本次交易对价，并可能触发历史转让协议效力与税务复核。 | G2: 以登记机关备案文本统一股权比例，由转让方提供更正说明、历史转让对价支付凭证及出资期限说明，并作为交易先决条件（F-01）。
A3: CT-02 | B3: HIGH | C3: 数据跨境表述与云架构实际部署不一致 | D3: 06_数据合规及业务资质__06.1_隐私政策与数据处理说明_2026 06_数据合规及业务资质__06.2_云服务账单及资源区域_202601-06 | E3: DATA-03、DATA-05 | F3: 隐私政策称无客户生产数据出境、海外仅测试/演示数据，但云账单显示境外区域（新加坡）部署含个人信息与账号标识符：prod-obs（新加坡，应用日志、IP、账号标识符（含个人信息））；sales-demo（新加坡，合成测试数据）。表述与部署互相矛盾，须核实是否落入《个人信息保护法》出境规制。 | G3: 要求目标公司澄清上述境外资源的数据属性（是否含个人信息/重要数据）、接收方与传输目的，补充跨境传输字段清单、告知同意记录、与境外接收方签订的标准合同/安全评估及个人信息保护影响评估（PIA）文件，作为事实问询并纳入陈述保证（F-08）。
A4: CT-03 | B4: HIGH | C4: 重大索赔/争议未纳入争议与或有负债清单 | D4: 03_重大合同及融资__03.1_重大合同台账_20260712 07_争议债务及保险__07.3_供应商索赔律师函_20260618 07_争议债务及保险__07.1_诉讼仲裁及或有负债清单_202607 | E4: DISP-01、DISP-02、CON-08 | F4: 以下合同的争议/索赔见于合同台账或律师函，但未列入07.1诉讼仲裁及或有负债清单：C-03（供应商丙科技有限公司，逾期付款，存在争议）。可能低估或有负债。 | G4: 将遗漏索赔补入争议/或有负债清单并说明原因，纳入赔偿（indemnity）事项（F-09）。

Sheet 统计摘要
A1: 云栖智联科技股份有限公司｜法律尽职调查第一轮资料核验统计摘要
A3: 一、按核验状态
A4: 核验状态 | B4: 公式计数 | C4: Python校验值
A5: 已满足 | B5: =COUNTIF(核验总表!D:D,"已满足") | C5: 12
A6: 部分满足 | B6: =COUNTIF(核验总表!D:D,"部分满足") | C6: 35
A7: 未满足 | B7: =COUNTIF(核验总表!D:D,"未满足") | C7: 2
A8: 不适用 | B8: =COUNTIF(核验总表!D:D,"不适用") | C8: 0
A9: 待确认 | B9: =COUNTIF(核验总表!D:D,"待确认") | C9: 0
A10: 资料冲突 | B10: =COUNTIF(核验总表!D:D,"资料冲突") | C10: 3
A11: 合计 | C11: 52
A13: 二、按风险等级
A14: 风险等级 | B14: 公式计数 | C14: Python校验值
A15: HIGH | B15: =COUNTIF(核验总表!H:H,"HIGH") | C15: 32
A16: MEDIUM | B16: =COUNTIF(核验总表!H:H,"MEDIUM") | C16: 8
A17: LOW | B17: =COUNTIF(核验总表!H:H,"LOW") | C17: 12
A18: INFO | B18: =COUNTIF(核验总表!H:H,"INFO") | C18: 0
A21: 三、按处置类型
A22: 处置类型 | B22: 公式计数 | C22: Python校验值
A23: CP | B23: =COUNTIF(核验总表!I:I,"CP") | C23: 26
A24: COVENANT | B24: =COUNTIF(核验总表!I:I,"COVENANT") | C24: 10
A25: INDEMNITY | B25: =COUNTIF(核验总表!I:I,"INDEMNITY") | C25: 3
A26: PRICE | B26: =COUNTIF(核验总表!I:I,"PRICE") | C26: 0
A27: RFI | B27: =COUNTIF(核验总表!I:I,"RFI") | C27: 13
A28: MONITOR | B28: =COUNTIF(核验总表!I:I,"MONITOR") | C28: 0
A29: NONE | B29: =COUNTIF(核验总表!I:I,"NONE") | C29: 0
A32: 四、按领域
A33: 领域 | B33: 公式计数 | C33: Python校验值
A34: 主体资格 | B34: =COUNTIF(核验总表!B:B,"主体资格") | C34: 7
A35: 股权出资 | B35: =COUNTIF(核验总表!B:B,"股权出资") | C35: 6
A36: 公司治理 | B36: =COUNTIF(核验总表!B:B,"公司治理") | C36: 5
A37: 重大合同 | B37: =COUNTIF(核验总表!B:B,"重大合同") | C37: 8
A38: 知识产权 | B38: =COUNTIF(核验总表!B:B,"知识产权") | C38: 7
A39: 劳动人事 | B39: =COUNTIF(核验总表!B:B,"劳动人事") | C39: 5
A40: 数据合规 | B40: =COUNTIF(核验总表!B:B,"数据合规") | C40: 6
A41: 业务资质 | B41: =COUNTIF(核验总表!B:B,"业务资质") | C41: 3
A42: 争议债务 | B42: =COUNTIF(核验总表!B:B,"争议债务") | C42: 3
A43: 物业资产 | B43: =COUNTIF(核验总表!B:B,"物业资产") | C43: 2
